<?xml version="1.0" encoding="utf-8"?>

<robot name="six_dof_spatial_manipulator" xmlns:xacro="http://ros.org/wiki/xacro">
  
  <material name="blue">
	  <color rgba="0 0 0.8 1"/>
   </material>

   <material name="green">
      <color rgba="0.0 0.8 0.0 1.0"/>
   </material>
   
   <material name="white">
	   <color rgba="1 1 1 1"/>
   </material>

   <link name="world">
      <visual>
         <geometry>
            <box size="0.35 0.45 0.16"/>
         </geometry>
         <material name="green"/>
         <origin rpy="0 0 0" xyz="0 0.17 -0.08"/>
       </visual>
   </link>

   <joint name="base_joint" type="fixed">
        <origin rpy="0 0 0" xyz="0 0 0"/>
        <parent link="world"/>
        <child link="base_link"/>
   </joint>

   <link name="base_link">
      <visual>
         <geometry>
            <box size="0.001 0.001 0.075"/> <!--0.085 0.09 0.025-->
         </geometry>
         <material name="white"/>
         <origin rpy="0 0 0" xyz="0 0 0.0375"/> <!--0 0 0.0125-->
       </visual>
   </link>

   <!--joint name="joint0" type="fixed">
        <origin rpy="0 0 0" xyz="0 0.0225 0.025"/>
        <parent link="base_link"/>
        <child link="link1"/>
   </joint-->

   <!--link name="link1">
      <visual>
         <geometry>
            <box size="0.02 0.04 0.05"/> 
         </geometry>
         <material name="green"/>
         <origin rpy="0 0 0" xyz="0 0 0.025"/>
       </visual>
   </link-->

   <joint name="joint1" type="revolute">
        <axis xyz="0 0 1"/>
        <limit effort="0.01" lower="-0.523" upper="2.62" velocity="0.05"/>
        <origin rpy="0 0 0" xyz="0 0 0.075"/>
        <parent link="base_link"/>
        <child link="link3"/>
   </joint>

   <!--link name="link2">
      <visual>
         <geometry>
            <box size="0.05 0.04 0.018"/>
         </geometry>
         <material name="blue"/>
         <origin rpy="0 0 0" xyz="0 -0.01 0.009"/>
       </visual>
   </link-->

   <!--joint name="joint2" type="fixed">
        <! <axis xyz="0 1 0"/>
        <limit effort="0.01" lower="-0.872" upper="3.5" velocity="6.0"/> >
        <origin rpy="0 0 0" xyz="-0.025 0 0.009"/>
        <parent link="link2"/>
        <child link="link3"/>
   </joint-->

   <link name="link3">
      <visual>
         <geometry>
            <box size="0.001 0.145 0.001"/> <!--0.001 0.105 0.001-->
         </geometry>
         <material name="white"/>
         <origin rpy="0 0 0" xyz="0 0.0725 0"/>
       </visual>
   </link>

   <joint name="joint3" type="revolute">
        <axis xyz="1 0 0"/>
        <limit effort="0.1" lower="-0.523" upper="1.047" velocity="0.5"/>
        <origin rpy="0 0 0" xyz="0 0.145 0"/>
        <parent link="link3"/>
        <child link="link4"/>
   </joint>

   <link name="link4">
      <visual>
         <geometry>
            <box size="0.001 0.07 0.001"/>
         </geometry>
         <material name="white"/>
         <origin rpy="0 0 0" xyz="0 0.035 0"/>
       </visual>
   </link>

   <joint name="joint4" type="revolute">
      <axis xyz="-1 0 0"/>
      <limit effort="0.01" lower="-1.407" upper="0.698" velocity="0.05"/>
      <origin rpy="0 0 0" xyz="0.01 0.07 0"/>
      <parent link="link4"/>
      <child link="link5"/>
   </joint>

   <link name="link5">
      <visual>
         <geometry>
            <box size="0.01 0.07 0.001"/>
         </geometry>
         <material name="green"/>
         <origin rpy="0 0 0" xyz="-0.005 0.035 0"/>
         </visual>
   </link>

   
   <joint name="joint5" type="revolute">
        <axis xyz="0 1 0"/>
        <limit effort="0.01" lower="-1.745" upper="1.396" velocity="0.05"/>
        <origin rpy="0 0 0" xyz="0 0.07 0"/>
        <parent link="link5"/>
        <child link="link6"/>
   </joint>

   <link name="link6">
      <visual>
         <geometry>
            <box size="0.015 0.025 0.001"/>
         </geometry>
         <material name="white"/>
         <origin rpy="0 0 0" xyz="0.0075 0.0125 0"/>
       </visual>
   </link>

   <joint name="joint6" type="revolute">
        <axis xyz="0 0 1"/>
        <limit effort="0.01" lower="0" upper="3.14" velocity="0.05"/>
        <origin rpy="0 0 0" xyz="0.015 0.025 0"/>
        <parent link="link6"/>
        <child link="endeff1"/>
   </joint>

   <link name="endeff1">
      <visual>
         <geometry>
            <box size="0.001 0.087 0.001"/>
         </geometry>
         <material name="white"/>
         <origin rpy="0 0 0" xyz="0 0.0435 0"/>
       </visual>
   </link> 

</robot>
