<?xml version="1.0" encoding="utf-8"?>
<!-- This URDF was automatically created by SolidWorks to URDF Exporter! Originally created by Stephen Brawner (brawner@gmail.com) 
     Commit Version: 1.6.0-4-g7f85cfe  Build Version: 1.6.7995.38578
     For more information, please see http://wiki.ros.org/sw_urdf_exporter -->
<robot name="dof6_Sm" xmlns:xacro="http://ros.org/wiki/xacro">
  

   <link name="world">
      <visual>
         <geometry>
            <box size="0.35 0.45 0.16"/>
         </geometry>
         <origin rpy="0 0 0" xyz="0 0.17 -0.08"/>
       </visual>
   </link>

	<joint name="base_joint" type="fixed">
		<parent link="world"/>
		<child link="base_link"/>
		<origin rpy="0 0 0" xyz="0.0 0.0 0.0"/>
	</joint>   

  <link name="base_link">
    <inertial>
      <origin
        xyz="-3.7554E-05 8.3267E-17 0.01275"
        rpy="0 0 0" />
      <mass
        value="0.028055" />
      <inertia
        ixx="2.1393E-05"
        ixy="4.1857E-21"
        ixz="6.4455E-16"
        iyy="8.7471E-06"
        iyz="-4.3775E-17"
        izz="2.3378E-05" />
    </inertial>
    <visual>
      <origin
        xyz="0 0 0"
        rpy="0 0 0" />
      <geometry>
        <mesh
          filename="package://dof6_sm/meshes/base.STL" />
      </geometry>
      <material
        name="">
        <color
          rgba="0.25098 0.25098 0.25098 1" />
      </material>
    </visual>
    <collision>
      <origin
        xyz="0 0 0"
        rpy="0 0 0" />
      <geometry>
        <mesh
          filename="package://dof6_sm/meshes/base.STL" />
      </geometry>
    </collision>
  </link>
 
  <joint name="joint0"
    type="fixed">
    <origin
      xyz="0 0 0"
      rpy="0 0 0" />
    <parent
      link="base_link" />
    <child
      link="link1" />
    <axis
      xyz="0 0 0" />
  </joint>
 
  <link name="link1">
    <inertial>
      <origin
        xyz="-0.021 0.00056434 0.048613"
        rpy="0 0 0" />
      <mass
        value="0.031565" />
      <inertia
        ixx="4.8514E-06"
        ixy="3.868E-10"
        ixz="-6.8731E-08"
        iyy="8.2695E-06"
        iyz="-8.0731E-08"
        izz="5.3773E-06" />
    </inertial>
    <visual>
      <origin
        xyz="0 0 0"
        rpy="0 0 0" />
      <geometry>
        <mesh
          filename="package://dof6_sm/meshes/link1.STL" />
      </geometry>
      <material
        name="">
        <color
          rgba="0.77647 0.75686 0.73725 1" />
      </material>
    </visual>
    <collision>
      <origin
        xyz="0 0 0"
        rpy="0 0 0" />
      <geometry>
        <mesh
          filename="package://dof6_sm/meshes/link1.STL" />
      </geometry>
    </collision>
  </link>

  <joint name="joint1"
    type="revolute">
    <origin
      xyz="0 0 0"
      rpy="0 0 0" />
    <parent
      link="link1" />
    <child
      link="link2" />
    <axis
      xyz="0 0 -1" />
    <limit
      lower="1.04"
      upper="5.411"
      effort="0.11"
      velocity="5.23" />
  </joint>
  
  <link name="link2">
    <inertial>
      <origin
        xyz="-0.00057106 0.00039272 0.086818"
        rpy="0 0 0" />
      <mass
        value="0.031763" />
      <inertia
        ixx="4.858E-06"
        ixy="-6.8731E-08"
        ixz="-3.868E-10"
        iyy="5.3856E-06"
        iyz="8.0731E-08"
        izz="8.2828E-06" />
    </inertial>
    <visual>
      <origin
        xyz="0 0 0"
        rpy="0 0 0" />
      <geometry>
        <mesh
          filename="package://dof6_sm/meshes/link2.STL" />
      </geometry>
      <material
        name="">
        <color
          rgba="1 1 1 1" />
      </material>
    </visual>
    <collision>
      <origin
        xyz="0 0 0"
        rpy="0 0 0" />
      <geometry>
        <mesh
          filename="package://dof6_sm/meshes/link2.STL" />
      </geometry>
    </collision>
  </link>
  
  <joint name="joint2"
    type="revolute">
    <origin
      xyz="0 0 0"
      rpy="0 0 0" />
    <parent
      link="link2" />
    <child
      link="link3" />
    <axis
      xyz="0 1 0" />
    <limit
      lower="-0.872"
      upper="3.5"
      effort="0.11"
      velocity="5.23" />
  </joint>
  
  <link name="link3">
    <inertial>
      <origin
        xyz="0.0095 0.0040229 0.14114"
        rpy="0 0 0" />
      <mass
        value="0.010037" />
      <inertia
        ixx="8.2317E-06"
        ixy="-1.4598E-17"
        ixz="-2.4403E-16"
        iyy="3.8653E-06"
        iyz="-4.2969E-16"
        izz="5.2872E-06" />
    </inertial>
    <visual>
      <origin
        xyz="0 0 0"
        rpy="0 0 0" />
      <geometry>
        <mesh
          filename="package://dof6_sm/meshes/link3.STL" />
      </geometry>
      <material
        name="">
        <color
          rgba="0.25098 0.25098 0.25098 1" />
      </material>
    </visual>
    <collision>
      <origin
        xyz="0 0 0"
        rpy="0 0 0" />
      <geometry>
        <mesh
          filename="package://dof6_sm/meshes/link3.STL" />
      </geometry>
    </collision>
  </link>

  <joint name="joint3"
    type="revolute">
    <origin
      xyz="0 0 0"
      rpy="0 0 0" />
    <parent
      link="link3" />
    <child
      link="link4" />
    <axis
      xyz="0 1 0" />
    <limit
      lower="-0.7"
      upper="4.014"
      effort="0.11"
      velocity="5.23" />
  </joint>  

  <link name="link4">
    <inertial>
      <origin
        xyz="-0.040285 0.00028958 0.19544"
        rpy="0 0 0" />
      <mass
        value="0.071856" />
      <inertia
        ixx="1.0238E-05"
        ixy="1.3746E-07"
        ixz="-7.736E-10"
        iyy="1.2854E-05"
        iyz="-1.6146E-07"
        izz="1.8576E-05" />
    </inertial>
    <visual>
      <origin
        xyz="0 0 0"
        rpy="0 0 0" />
      <geometry>
        <mesh
          filename="package://dof6_sm/meshes/link4.STL" />
      </geometry>
      <material
        name="">
        <color
          rgba="0.25098 0.25098 0.25098 1" />
      </material>
    </visual>
    <collision>
      <origin
        xyz="0 0 0"
        rpy="0 0 0" />
      <geometry>
        <mesh
          filename="package://dof6_sm/meshes/link4.STL" />
      </geometry>
    </collision>
  </link>
  
  <joint name="joint4"
    type="revolute">
    <origin
      xyz="0.12 9.93125E-05 0"
      rpy="0 0 0" />
    <parent
      link="link4" />
    <child
      link="link5" />
    <axis
      xyz="0 1 0" />
    <limit
      lower="1.134"
      upper="4.88"
      effort="0.11"
      velocity="5.23" />
  </joint>
  
  <link name="link5">
    <inertial>
      <origin
        xyz="-0.110499999999125 -0.00034390217564309 0.238945413859527"
        rpy="0 0 0" />
      <mass
        value="0.0321602958491818" />
      <inertia
        ixx="1.07128950131684E-05"
        ixy="5.63938887391421E-12"
        ixz="-8.63080995082527E-17"
        iyy="5.76337201343074E-06"
        iyz="-6.97331998439793E-08"
        izz="6.9375395044212E-06" />
    </inertial>
    <visual>
      <origin
        xyz="0 0 0"
        rpy="0 0 0" />
      <geometry>
        <mesh
          filename="package://dof6_sm/meshes/link5.STL" />
      </geometry>
      <material
        name="">
        <color
          rgba="0.250980392156863 0.250980392156863 0.250980392156863 1" />
      </material>
    </visual>
    <collision>
      <origin
        xyz="0 0 0"
        rpy="0 0 0" />
      <geometry>
        <mesh
          filename="package://dof6_sm/meshes/link5.STL" />
      </geometry>
    </collision>
  </link>
  
  <joint name="joint5"
    type="revolute">
    <origin
      xyz="0 0 0"
      rpy="0 0 0" />
    <parent
      link="link5" />
    <child
      link="link6" />
    <axis
      xyz="0 0 1" />
    <limit
      lower="-2.44"
      upper="2.04"
      effort="0.11"
      velocity="5.23" />
  </joint>
  
  <link
    name="link6">
    <inertial>
      <origin
        xyz="-0.0926221566328444 -0.00922986881897171 0.298231606382165"
        rpy="0 0 0" />
      <mass
        value="0.0352754374130566" />
      <inertia
        ixx="6.68045831435732E-06"
        ixy="1.06110371340762E-07"
        ixz="-2.82993525758347E-09"
        iyy="5.08464329195728E-06"
        iyz="9.88377876393417E-08"
        izz="8.50070389014964E-06" />
    </inertial>
    <visual>
      <origin
        xyz="0 0 0"
        rpy="0 0 0" />
      <geometry>
        <mesh
          filename="package://dof6_sm/meshes/link6.STL" />
      </geometry>
      <material
        name="">
        <color
          rgba="1 1 1 1" />
      </material>
    </visual>
    <collision>
      <origin
        xyz="0 0 0"
        rpy="0 0 0" />
      <geometry>
        <mesh
          filename="package://dof6_sm/meshes/link6.STL" />
      </geometry>
    </collision>
  </link>
  
  <joint name="joint6_1"
    type="revolute">
    <origin
      xyz="0 0 0"
      rpy="0 0 0" />
    <parent
      link="link6" />
    <child
      link="endeff1" />
    <axis
      xyz="1 0 0" />
    <limit
      lower="0"
      upper="0.5"
      effort="0.11"
      velocity="5.23" />
  </joint>
  
  <link name="endeff1">
    <inertial>
      <origin
        xyz="-0.11236 -0.0045521 0.29577"
        rpy="0 0 0" />
      <mass
        value="0.0045643" />
      <inertia
        ixx="7.8305E-07"
        ixy="1.3212E-22"
        ixz="-1.0599E-21"
        iyy="6.7856E-07"
        iyz="1.2758E-07"
        izz="1.1747E-07" />
    </inertial>
    <visual>
      <origin
        xyz="0 0 0"
        rpy="0 0 0" />
      <geometry>
        <mesh
          filename="package://dof6_sm/meshes/endeff1.STL" />
      </geometry>
      <material
        name="">
        <color
          rgba="0.66667 0.69412 0.76471 1" />
      </material>
    </visual>
    <collision>
      <origin
        xyz="0 0 0"
        rpy="0 0 0" />
      <geometry>
        <mesh
          filename="package://dof6_sm/meshes/endeff1.STL" />
      </geometry>
    </collision>
  </link>
  
 <joint name="joint6_2"
    type="revolute">
    <origin
      xyz="0 0 0"
      rpy="0 0 0" />
    <parent
      link="link6" />
    <child
      link="endeff2" />
    <axis
      xyz="1 0 0" />
    <limit
      lower="-0.5"
      upper="0"
      effort="0.11"
      velocity="5.23" />
  </joint>
  
  <link name="endeff2">
    <inertial>
      <origin
        xyz="-0.11195 0.02306 0.29489"
        rpy="0 0 0" />
      <mass
        value="0.0045576" />
      <inertia
        ixx="7.9981E-07"
        ixy="-1.0914E-22"
        ixz="-5.5589E-22"
        iyy="7.0405E-07"
        iyz="-1.2735E-07"
        izz="1.115E-07" />
    </inertial>
    <visual>
      <origin
        xyz="0 0 0"
        rpy="0 0 0" />
      <geometry>
        <mesh
          filename="package://dof6_sm/meshes/endeff2.STL" />
      </geometry>
      <material
        name="">
        <color
          rgba="0.66667 0.69412 0.76471 1" />
      </material>
    </visual>
    <collision>
      <origin
        xyz="0 0 0"
        rpy="0 0 0" />
      <geometry>
        <mesh
          filename="package://dof6_sm/meshes/endeff2.STL" />
      </geometry>
    </collision>
  </link>
  
     <transmission name="link2_trans">
	   <type>transmission_interface/SimpleTransmission</type>
	   <joint name="joint1">
		   <hardwareInterface>hardware_interface/PositionJointInterface</hardwareInterface>
	   </joint>
	   <actuator name="link2_motor">
		   <hardwareInterface>hardware_interface/PositionJointInterface</hardwareInterface>
		   <mechanicalReduction>1</mechanicalReduction>
	   </actuator>
   </transmission>

   <transmission name="link3_trans">
	   <type>transmission_interface/SimpleTransmission</type>
	   <joint name="joint2">
		   <hardwareInterface>hardware_interface/PositionJointInterface</hardwareInterface>
	   </joint>
	   <actuator name="link3_motor">
		   <hardwareInterface>hardware_interface/PositionJointInterface</hardwareInterface>
		   <mechanicalReduction>1</mechanicalReduction>
	   </actuator>
   </transmission>

   <transmission name="link4_trans">
	   <type>transmission_interface/SimpleTransmission</type>
	   <joint name="joint3">
		   <hardwareInterface>hardware_interface/PositionJointInterface</hardwareInterface>
	   </joint>
	   <actuator name="link4_motor">
		   <hardwareInterface>hardware_interface/PositionJointInterface</hardwareInterface>
		   <mechanicalReduction>1</mechanicalReduction>
	   </actuator>
   </transmission>

   <transmission name="link5_trans">
	   <type>transmission_interface/SimpleTransmission</type>
	   <joint name="joint4">
		   <hardwareInterface>hardware_interface/PositionJointInterface</hardwareInterface>
	   </joint>
	   <actuator name="link5_motor">
		   <hardwareInterface>hardware_interface/PositionJointInterface</hardwareInterface>
		   <mechanicalReduction>1</mechanicalReduction>
	   </actuator>
   </transmission>

   <transmission name="link6_trans">
	   <type>transmission_interface/SimpleTransmission</type>
	   <joint name="joint5">
		   <hardwareInterface>hardware_interface/PositionJointInterface</hardwareInterface>
	   </joint>
	   <actuator name="link6_motor">
		   <hardwareInterface>hardware_interface/PositionJointInterface</hardwareInterface>
		   <mechanicalReduction>1</mechanicalReduction>
	   </actuator>
   </transmission>

   <transmission name="endeff1_trans">
	   <type>transmission_interface/SimpleTransmission</type>
	   <joint name="joint6_1">
		   <hardwareInterface>hardware_interface/PositionJointInterface</hardwareInterface>
	   </joint>
	   <actuator name="endeff1_motor">
		   <hardwareInterface>hardware_interface/PositionJointInterface</hardwareInterface>
		   <mechanicalReduction>1</mechanicalReduction>
	   </actuator>
   </transmission>
  
   <gazebo>
	   <plugin name="control" filename="libgazebo_ros_control.so">
		   <robotNamespace>/six_dof_spatial_manipulator</robotNamespace>
	   </plugin>
   </gazebo>

   <gazebo reference="link2">
	   <selfCollide>true</selfCollide>
   </gazebo>

   <gazebo reference="link3">
	   <selfCollide>true</selfCollide>
   </gazebo>

   <gazebo reference="link4">
	   <selfCollide>true</selfCollide>
   </gazebo>

   <gazebo reference="link5">
	   <selfCollide>true</selfCollide>
   </gazebo>

   <gazebo reference="link6">
	   <selfCollide>true</selfCollide>
   </gazebo>

   <gazebo reference="endeff1">
	   <selfCollide>true</selfCollide>
   </gazebo>

</robot>
  
